Workbook

Sheet Costos por día
A1: Costos por día y actividad — Travesía Ruta 66 (nov-2027)
A2: Cada línea toma su costo unitario de 'Supuestos y fuentes' y aplica el ajuste a 2027. Tipo: FIJO = no depende de la cantidad de participantes; VARIABLE = escala con participantes/autos. Las cantidades son fórmulas (pax, staff, autos, habitaciones, vehículos).
A4: Día | B4: Fecha | C4: Actividad / rubro | D4: Tipo | E4: Costo unitario 2026 | F4: Costo unit. 2027 | G4: Unidad | H4: Cant. esc. 1 | I4: Total esc. 1 | J4: Cant. esc. 2 | K4: Total esc. 2 | L4: Notas
A5: Transversal | B5: 4–11 nov | C5: Vuelo EZE–LAS turista — participantes | D5: VARIABLE | E5: ='Supuestos y fuentes'!$C$16 -> 1150 | F5: =E5*(1+'Supuestos y fuentes'!$C$11) -> 1219 | G5: persona | H5: ='Supuestos y fuentes'!$C$6 -> 5 | I5: =F5*H5 -> 6095 | J5: ='Supuestos y fuentes'!$C$7 -> 15 | K5: =F5*J5 -> 18285 | L5: Incluido en el precio. Upgrade a business se cotiza aparte (ver hoja Rentabilidad)
A6: Transversal | B6: 4–11 nov | C6: Vuelo EZE–LAS turista — staff (3) | D6: FIJO | E6: ='Supuestos y fuentes'!$C$16 -> 1150 | F6: =E6*(1+'Supuestos y fuentes'!$C$11) -> 1219 | G6: persona | H6: ='Supuestos y fuentes'!$C$9 -> 3 | I6: =F6*H6 -> 3657 | J6: ='Supuestos y fuentes'!$C$9 -> 3 | K6: =F6*J6 -> 3657 | L6: Javier, Jorge y Alejandro
A7: Transversal | B7: 4–11 nov | C7: Asistencia al viajero / seguro médico (participantes + staff) | D7: VARIABLE | E7: ='Supuestos y fuentes'!$C$18*'Supuestos y fuentes'!$C$19 -> 81 | F7: =E7*(1+'Supuestos y fuentes'!$C$11) -> 85.86 | G7: persona | H7: ='Supuestos y fuentes'!$C$6+'Supuestos y fuentes'!$C$9 -> 8 | I7: =F7*H7 -> 686.88 | J7: ='Supuestos y fuentes'!$C$7+'Supuestos y fuentes'!$C$9 -> 18 | K7: =F7*J7 -> 1545.48 | L7: Cobertura USD 150.000+, incluye deportes/motor
A8: Transversal | B8: 4–11 nov | C8: Kit de bienvenida (campera, gorra, placa, roadbook) | D8: VARIABLE | E8: ='Supuestos y fuentes'!$C$73 -> 250 | F8: =E8*(1+'Supuestos y fuentes'!$C$11) -> 265 | G8: persona | H8: ='Supuestos y fuentes'!$C$6 -> 5 | I8: =F8*H8 -> 1325 | J8: ='Supuestos y fuentes'!$C$7 -> 15 | K8: =F8*J8 -> 3975
A9: Transversal | B9: 4–11 nov | C9: Producción foto/video (equipo, drone, edición, música) | D9: FIJO | E9: ='Supuestos y fuentes'!$C$72 -> 3000 | F9: =E9*(1+'Supuestos y fuentes'!$C$11) -> 3180 | G9: fijo | H9: =1 -> 1 | I9: =F9*H9 -> 3180 | J9: =1 -> 1 | K9: =F9*J9 -> 3180 | L9: Material para redes del 2º viaje
A10: Transversal | B10: 4–11 nov | C10: Pre-viaje: reuniones, seguro RC organizador, gestoría | D10: FIJO | E10: ='Supuestos y fuentes'!$C$74 -> 2000 | F10: =E10*(1+'Supuestos y fuentes'!$C$11) -> 2120 | G10: fijo | H10: =1 -> 1 | I10: =F10*H10 -> 2120 | J10: =1 -> 1 | K10: =F10*J10 -> 2120
A11: Transversal | B11: 4–11 nov | C11: Vehículo de apoyo (pickup) — alquiler | D11: FIJO | E11: ='Supuestos y fuentes'!$C$28*'Supuestos y fuentes'!$C$29 -> 665 | F11: =E11*(1+'Supuestos y fuentes'!$C$11) -> 704.9 | G11: fijo | H11: =1 -> 1 | I11: =F11*H11 -> 704.9 | J11: =1 -> 1 | K11: =F11*J11 -> 704.9 | L11: Mecánico (Javier) + herramientas + equipaje
A12: Transversal | B12: 4–11 nov | C12: Herramientas, repuestos y combustible del vehículo de apoyo | D12: FIJO | E12: ='Supuestos y fuentes'!$C$30 -> 900 | F12: =E12*(1+'Supuestos y fuentes'!$C$11) -> 954 | G12: fijo | H12: =1 -> 1 | I12: =F12*H12 -> 954 | J12: =1 -> 1 | K12: =F12*J12 -> 954
A13: Día 0 | B13: jue 4 nov | C13: Traslado aeropuerto → The Venetian (sprinter con chofer) | D13: FIJO | E13: ='Supuestos y fuentes'!$C$68 -> 550 | F13: =E13*(1+'Supuestos y fuentes'!$C$11) -> 583 | G13: vehículo | H13: ='Supuestos y fuentes'!$C$81 -> 1 | I13: =F13*H13 -> 583 | J13: ='Supuestos y fuentes'!$C$82 -> 2 | K13: =F13*J13 -> 1166 | L13: Hasta 14 pax por sprinter; con 15 pax + staff se necesitan 2
A14: Día 0 | B14: jue 4 nov | C14: The Venetian — suite por participante (noche 1) | D14: VARIABLE | E14: ='Supuestos y fuentes'!$C$32 -> 520 | F14: =E14*(1+'Supuestos y fuentes'!$C$11) -> 551.2 | G14: habitación | H14: ='Supuestos y fuentes'!$C$6 -> 5 | I14: =F14*H14 -> 2756 | J14: ='Supuestos y fuentes'!$C$7 -> 15 | K14: =F14*J14 -> 8268 | L14: Single. A 5 min del Convention Center
A15: Día 0 | B15: jue 4 nov | C15: The Venetian — habitaciones staff (noche 1) | D15: FIJO | E15: ='Supuestos y fuentes'!$C$32 -> 520 | F15: =E15*(1+'Supuestos y fuentes'!$C$11) -> 551.2 | G15: habitación | H15: ='Supuestos y fuentes'!$C$10 -> 2 | I15: =F15*H15 -> 1102.4 | J15: ='Supuestos y fuentes'!$C$10 -> 2 | K15: =F15*J15 -> 1102.4
A16: Día 0 | B16: jue 4 nov | C16: Cena de bienvenida en The Venetian | D16: VARIABLE | E16: ='Supuestos y fuentes'!$C$40 -> 160 | F16: =E16*(1+'Supuestos y fuentes'!$C$11) -> 169.6 | G16: persona | H16: ='Supuestos y fuentes'!$C$6+'Supuestos y fuentes'!$C$9 -> 8 | I16: =F16*H16 -> 1356.8 | J16: ='Supuestos y fuentes'!$C$7+'Supuestos y fuentes'!$C$9 -> 18 | K16: =F16*J16 -> 3052.8 | L16: Delmonico Steakhouse o Bouchon
A17: Día 1 | B17: vie 5 nov | C17: Desayuno | D17: VARIABLE | E17: ='Supuestos y fuentes'!$C$39 -> 30 | F17: =E17*(1+'Supuestos y fuentes'!$C$11) -> 31.8 | G17: persona | H17: ='Supuestos y fuentes'!$C$6+'Supuestos y fuentes'!$C$9 -> 8 | I17: =F17*H17 -> 254.4 | J17: ='Supuestos y fuentes'!$C$7+'Supuestos y fuentes'!$C$9 -> 18 | K17: =F17*J17 -> 572.4
A18: Día 1 | B18: vie 5 nov | C18: Entrada SEMA Show (viernes público) | D18: VARIABLE | E18: ='Supuestos y fuentes'!$C$54 -> 130 | F18: =E18*(1+'Supuestos y fuentes'!$C$11) -> 137.8 | G18: persona | H18: ='Supuestos y fuentes'!$C$6+'Supuestos y fuentes'!$C$9 -> 8 | I18: =F18*H18 -> 1102.4 | J18: ='Supuestos y fuentes'!$C$7+'Supuestos y fuentes'!$C$9 -> 18 | K18: =F18*J18 -> 2480.4 | L18: USD 130 en 2026 — poner 0 si en 2027 vuelve a ser gratuito
A19: Día 1 | B19: vie 5 nov | C19: Traslados Strip (sprinter 3 h mínimo) | D19: FIJO | E19: ='Supuestos y fuentes'!$C$70*3 -> 720 | F19: =E19*(1+'Supuestos y fuentes'!$C$11) -> 763.2 | G19: vehículo | H19: ='Supuestos y fuentes'!$C$81 -> 1 | I19: =F19*H19 -> 763.2 | J19: ='Supuestos y fuentes'!$C$82 -> 2 | K19: =F19*J19 -> 1526.4 | L19: Convention Center ↔ hotel ↔ cena
A20: Día 1 | B20: vie 5 nov | C20: Cena Hard Rock Café / Coyote Ugly | D20: VARIABLE | E20: ='Supuestos y fuentes'!$C$41 -> 70 | F20: =E20*(1+'Supuestos y fuentes'!$C$11) -> 74.2 | G20: persona | H20: ='Supuestos y fuentes'!$C$6+'Supuestos y fuentes'!$C$9 -> 8 | I20: =F20*H20 -> 593.6 | J20: ='Supuestos y fuentes'!$C$7+'Supuestos y fuentes'!$C$9 -> 18 | K20: =F20*J20 -> 1335.6
A21: Día 1 | B21: vie 5 nov | C21: The Venetian — suite por participante (noche 2) | D21: VARIABLE | E21: ='Supuestos y fuentes'!$C$32 -> 520 | F21: =E21*(1+'Supuestos y fuentes'!$C$11) -> 551.2 | G21: habitación | H21: ='Supuestos y fuentes'!$C$6 -> 5 | I21: =F21*H21 -> 2756 | J21: ='Supuestos y fuentes'!$C$7 -> 15 | K21: =F21*J21 -> 8268
A22: Día 1 | B22: vie 5 nov | C22: The Venetian — habitaciones staff (noche 2) | D22: FIJO | E22: ='Supuestos y fuentes'!$C$32 -> 520 | F22: =E22*(1+'Supuestos y fuentes'!$C$11) -> 551.2 | G22: habitación | H22: ='Supuestos y fuentes'!$C$10 -> 2 | I22: =F22*H22 -> 1102.4 | J22: ='Supuestos y fuentes'!$C$10 -> 2 | K22: =F22*J22 -> 1102.4
A23: Día 2 | B23: sáb 6 nov | C23: Desayuno | D23: VARIABLE | E23: ='Supuestos y fuentes'!$C$39 -> 30 | F23: =E23*(1+'Supuestos y fuentes'!$C$11) -> 31.8 | G23: persona | H23: ='Supuestos y fuentes'!$C$6+'Supuestos y fuentes'!$C$9 -> 8 | I23: =F23*H23 -> 254.4 | J23: ='Supuestos y fuentes'!$C$7+'Supuestos y fuentes'!$C$9 -> 18 | K23: =F23*J23 -> 572.4
A24: Día 2 | B24: sáb 6 nov | C24: Alquiler auto clásico (5 días) | D24: VARIABLE | E24: ='Supuestos y fuentes'!$C$21*'Supuestos y fuentes'!$C$22 -> 2375 | F24: =E24*(1+'Supuestos y fuentes'!$C$11) -> 2517.5 | G24: auto | H24: ='Supuestos y fuentes'!$C$77 -> 5 | I24: =F24*H24 -> 12587.5 | J24: ='Supuestos y fuentes'!$C$78 -> 15 | K24: =F24*J24 -> 37762.5 | L24: Depósito de garantía (USD 2.500–5.000 por auto) no es costo: se devuelve
A25: Día 2 | B25: sáb 6 nov | C25: Seguro por auto (5 días) | D25: VARIABLE | E25: ='Supuestos y fuentes'!$C$23*'Supuestos y fuentes'!$C$22 -> 225 | F25: =E25*(1+'Supuestos y fuentes'!$C$11) -> 238.5 | G25: auto | H25: ='Supuestos y fuentes'!$C$77 -> 5 | I25: =F25*H25 -> 1192.5 | J25: ='Supuestos y fuentes'!$C$78 -> 15 | K25: =F25*J25 -> 3577.5
A26: Día 2 | B26: sáb 6 nov | C26: Combustible por auto (recorrido completo) | D26: VARIABLE | E26: ='Supuestos y fuentes'!$C$79 -> 349.59602 | F26: =E26*(1+'Supuestos y fuentes'!$C$11) -> 370.57178 | G26: auto | H26: ='Supuestos y fuentes'!$C$77 -> 5 | I26: =F26*H26 -> 1852.8589 | J26: ='Supuestos y fuentes'!$C$78 -> 15 | K26: =F26*J26 -> 5558.5768 | L26: Ver km y consumo en Supuestos
A27: Día 2 | B27: sáb 6 nov | C27: Evento de entrega de autos — Fremont Street | D27: FIJO | E27: ='Supuestos y fuentes'!$C$55 -> 1500 | F27: =E27*(1+'Supuestos y fuentes'!$C$11) -> 1590 | G27: fijo | H27: =1 -> 1 | I27: =F27*H27 -> 1590 | J27: =1 -> 1 | K27: =F27*J27 -> 1590 | L27: Permiso + montaje + sesión de fotos
A28: Día 2 | B28: sáb 6 nov | C28: Almuerzo en Boulder City | D28: VARIABLE | E28: ='Supuestos y fuentes'!$C$42 -> 35 | F28: =E28*(1+'Supuestos y fuentes'!$C$11) -> 37.1 | G28: persona | H28: ='Supuestos y fuentes'!$C$6+'Supuestos y fuentes'!$C$9 -> 8 | I28: =F28*H28 -> 296.8 | J28: ='Supuestos y fuentes'!$C$7+'Supuestos y fuentes'!$C$9 -> 18 | K28: =F28*J28 -> 667.8
A29: Día 2 | B29: sáb 6 nov | C29: Hoover Dam — Dam Tour oficial | D29: VARIABLE | E29: ='Supuestos y fuentes'!$C$56 -> 30 | F29: =E29*(1+'Supuestos y fuentes'!$C$11) -> 31.8 | G29: persona | H29: ='Supuestos y fuentes'!$C$6+'Supuestos y fuentes'!$C$9 -> 8 | I29: =F29*H29 -> 254.4 | J29: ='Supuestos y fuentes'!$C$7+'Supuestos y fuentes'!$C$9 -> 18 | K29: =F29*J29 -> 572.4 | L29: Último tour 15:30; el atardecer es en miradores y puente
A30: Día 2 | B30: sáb 6 nov | C30: Hoover Dam — guía privado y experiencia al atardecer | D30: FIJO | E30: ='Supuestos y fuentes'!$C$57 -> 1200 | F30: =E30*(1+'Supuestos y fuentes'!$C$11) -> 1272 | G30: fijo | H30: =1 -> 1 | I30: =F30*H30 -> 1272 | J30: =1 -> 1 | K30: =F30*J30 -> 1272
A31: Día 2 | B31: sáb 6 nov | C31: Boulder Dam Hotel — habitaciones | D31: VARIABLE | E31: ='Supuestos y fuentes'!$C$33 -> 160 | F31: =E31*(1+'Supuestos y fuentes'!$C$11) -> 169.6 | G31: habitación | H31: ='Supuestos y fuentes'!$C$6+'Supuestos y fuentes'!$C$10 -> 7 | I31: =F31*H31 -> 1187.2 | J31: ='Supuestos y fuentes'!$C$7+'Supuestos y fuentes'!$C$10 -> 17 | K31: =F31*J31 -> 2883.2 | L31: Hotel de 20 habitaciones: con 15 pax, reservar completo
A32: Día 2 | B32: sáb 6 nov | C32: Cena en Boulder Dam Hotel | D32: VARIABLE | E32: ='Supuestos y fuentes'!$C$43 -> 70 | F32: =E32*(1+'Supuestos y fuentes'!$C$11) -> 74.2 | G32: persona | H32: ='Supuestos y fuentes'!$C$6+'Supuestos y fuentes'!$C$9 -> 8 | I32: =F32*H32 -> 593.6 | J32: ='Supuestos y fuentes'!$C$7+'Supuestos y fuentes'!$C$9 -> 18 | K32: =F32*J32 -> 1335.6
A33: Día 3 | B33: dom 7 nov | C33: Desayuno | D33: VARIABLE | E33: ='Supuestos y fuentes'!$C$39 -> 30 | F33: =E33*(1+'Supuestos y fuentes'!$C$11) -> 31.8 | G33: persona | H33: ='Supuestos y fuentes'!$C$6+'Supuestos y fuentes'!$C$9 -> 8 | I33: =F33*H33 -> 254.4 | J33: ='Supuestos y fuentes'!$C$7+'Supuestos y fuentes'!$C$9 -> 18 | K33: =F33*J33 -> 572.4
A34: Día 3 | B34: dom 7 nov | C34: Almuerzo diner en Kingman (Mr. D'z) | D34: VARIABLE | E34: ='Supuestos y fuentes'!$C$44 -> 28 | F34: =E34*(1+'Supuestos y fuentes'!$C$11) -> 29.68 | G34: persona | H34: ='Supuestos y fuentes'!$C$6+'Supuestos y fuentes'!$C$9 -> 8 | I34: =F34*H34 -> 237.44 | J34: ='Supuestos y fuentes'!$C$7+'Supuestos y fuentes'!$C$9 -> 18 | K34: =F34*J34 -> 534.24 | L34: Tras Oatman (burros, tiroteo escenificado)
A35: Día 3 | B35: dom 7 nov | C35: Parada en Seligman (Snow Cap) | D35: VARIABLE | E35: ='Supuestos y fuentes'!$C$45 -> 12 | F35: =E35*(1+'Supuestos y fuentes'!$C$11) -> 12.72 | G35: persona | H35: ='Supuestos y fuentes'!$C$6+'Supuestos y fuentes'!$C$9 -> 8 | I35: =F35*H35 -> 101.76 | J35: ='Supuestos y fuentes'!$C$7+'Supuestos y fuentes'!$C$9 -> 18 | K35: =F35*J35 -> 228.96 | L35: Cuna del renacimiento de la Ruta 66
A36: Día 3 | B36: dom 7 nov | C36: Motel años 50 en Williams — habitaciones | D36: VARIABLE | E36: ='Supuestos y fuentes'!$C$34 -> 140 | F36: =E36*(1+'Supuestos y fuentes'!$C$11) -> 148.4 | G36: habitación | H36: ='Supuestos y fuentes'!$C$6+'Supuestos y fuentes'!$C$10 -> 7 | I36: =F36*H36 -> 1038.8 | J36: ='Supuestos y fuentes'!$C$7+'Supuestos y fuentes'!$C$10 -> 17 | K36: =F36*J36 -> 2522.8 | L36: El Rancho Motel / The Lodge on Route 66
A37: Día 3 | B37: dom 7 nov | C37: Fiesta rock & roll (banda, jukebox, neón, barra) | D37: FIJO | E37: ='Supuestos y fuentes'!$C$58 -> 2500 | F37: =E37*(1+'Supuestos y fuentes'!$C$11) -> 2650 | G37: fijo | H37: =1 -> 1 | I37: =F37*H37 -> 2650 | J37: =1 -> 1 | K37: =F37*J37 -> 2650
A38: Día 3 | B38: dom 7 nov | C38: Cena de la fiesta | D38: VARIABLE | E38: ='Supuestos y fuentes'!$C$46 -> 60 | F38: =E38*(1+'Supuestos y fuentes'!$C$11) -> 63.6 | G38: persona | H38: ='Supuestos y fuentes'!$C$6+'Supuestos y fuentes'!$C$9 -> 8 | I38: =F38*H38 -> 508.8 | J38: ='Supuestos y fuentes'!$C$7+'Supuestos y fuentes'!$C$9 -> 18 | K38: =F38*J38 -> 1144.8
A39: Día 4 | B39: lun 8 nov | C39: Desayuno | D39: VARIABLE | E39: ='Supuestos y fuentes'!$C$39 -> 30 | F39: =E39*(1+'Supuestos y fuentes'!$C$11) -> 31.8 | G39: persona | H39: ='Supuestos y fuentes'!$C$6+'Supuestos y fuentes'!$C$9 -> 8 | I39: =F39*H39 -> 254.4 | J39: ='Supuestos y fuentes'!$C$7+'Supuestos y fuentes'!$C$9 -> 18 | K39: =F39*J39 -> 572.4
A40: Día 4 | B40: lun 8 nov | C40: Ingreso Gran Cañón por vehículo | D40: VARIABLE | E40: ='Supuestos y fuentes'!$C$59 -> 35 | F40: =E40*(1+'Supuestos y fuentes'!$C$11) -> 37.1 | G40: vehículo | H40: ='Supuestos y fuentes'!$C$77+1 -> 6 | I40: =F40*H40 -> 222.6 | J40: ='Supuestos y fuentes'!$C$78+1 -> 16 | K40: =F40*J40 -> 593.6 | L40: Autos + vehículo de apoyo
A41: Día 4 | B41: lun 8 nov | C41: Recargo no residente Gran Cañón (por persona) | D41: VARIABLE | E41: ='Supuestos y fuentes'!$C$60 -> 100 | F41: =E41*(1+'Supuestos y fuentes'!$C$11) -> 106 | G41: persona | H41: ='Supuestos y fuentes'!$C$6+'Supuestos y fuentes'!$C$9 -> 8 | I41: =F41*H41 -> 848 | J41: ='Supuestos y fuentes'!$C$7+'Supuestos y fuentes'!$C$9 -> 18 | K41: =F41*J41 -> 1908 | L41: Política NPS 2026, confirmar para 2027
...

Sheet Escenarios 5 vs 15
A1: Escenarios: 5 participantes vs. 15 participantes — costo fijo vs. variable
A2: Todas las cifras salen de 'Costos por día' (SUMIFS). Cambiá los supuestos y esta hoja se actualiza.
A4: Concepto | B4: Escenario 1 | C4: Escenario 2 | D4: Notas
A5: Participantes | B5: ='Supuestos y fuentes'!$C$6 -> 5 | C5: ='Supuestos y fuentes'!$C$7 -> 15
A6: Staff | B6: ='Supuestos y fuentes'!$C$9 -> 3 | C6: ='Supuestos y fuentes'!$C$9 -> 3
A7: Autos clásicos | B7: ='Supuestos y fuentes'!$C$77 -> 5 | C7: ='Supuestos y fuentes'!$C$78 -> 15
A8: Costos FIJOS (no dependen de los participantes) | B8: =SUMIFS('Costos por día'!$I$5:$I$61,'Costos por día'!$D$5:$D$61,"FIJO") -> 24639.7 | C8: =SUMIFS('Costos por día'!$K$5:$K$61,'Costos por día'!$D$5:$D$61,"FIJO") -> 27766.7 | D8: Staff, producción, vehículo de apoyo, eventos privados, traslados grupales
A9: Costos VARIABLES (escalan con participantes/autos) | B9: =SUMIFS('Costos por día'!$I$5:$I$61,'Costos por día'!$D$5:$D$61,"VARIABLE") -> 61744.979 | C9: =SUMIFS('Costos por día'!$K$5:$K$61,'Costos por día'!$D$5:$D$61,"VARIABLE") -> 165408.7 | D9: Vuelos, autos, hoteles, comidas, actividades por persona
A10: Costos directos | B10: =B8+B9 -> 86384.679 | C10: =C8+C9 -> 193175.4
A11: Contingencia | B11: =B10*'Supuestos y fuentes'!$C$12 -> 6910.7743 | C11: =C10*'Supuestos y fuentes'!$C$12 -> 15454.032 | D11: Sobre costos directos
A12: Costos financieros / cobro | B12: =B5*'Supuestos y fuentes'!$C$8*'Supuestos y fuentes'!$C$13 -> 4500 | C12: =C5*'Supuestos y fuentes'!$C$8*'Supuestos y fuentes'!$C$13 -> 13500 | D12: Sobre ingresos
A13: COSTO TOTAL | B13: =B10+B11+B12 -> 97795.453 | C13: =C10+C11+C12 -> 222129.43
A14: Costo total por participante | B14: =IF(B5=0,0,B13/B5) -> 19559.091 | C14: =IF(C5=0,0,C13/C5) -> 14808.629
A15: Costo fijo por participante | B15: =IF(B5=0,0,B8/B5) -> 4927.94 | C15: =IF(C5=0,0,C8/C5) -> 1851.1133 | D15: Acá está el apalancamiento de escala
A16: Costo variable por participante | B16: =IF(B5=0,0,B9/B5) -> 12348.996 | C16: =IF(C5=0,0,C9/C5) -> 11027.246
A18: Desglose por día
A19: Día | B19: Escenario 1 | C19: Escenario 2 | D19: Esc. 1 por participante | E19: Esc. 2 por participante
A20: Transversal | B20: =SUMIFS('Costos por día'!$I$5:$I$61,'Costos por día'!$A$5:$A$61,A20) -> 18722.78 | C20: =SUMIFS('Costos por día'!$K$5:$K$61,'Costos por día'!$A$5:$A$61,A20) -> 34421.38 | D20: =IF($B$5=0,0,B20/$B$5) -> 3744.556 | E20: =IF($C$5=0,0,C20/$C$5) -> 2294.7587
A21: Día 0 | B21: =SUMIFS('Costos por día'!$I$5:$I$61,'Costos por día'!$A$5:$A$61,A21) -> 5798.2 | C21: =SUMIFS('Costos por día'!$K$5:$K$61,'Costos por día'!$A$5:$A$61,A21) -> 13589.2 | D21: =IF($B$5=0,0,B21/$B$5) -> 1159.64 | E21: =IF($C$5=0,0,C21/$C$5) -> 905.94667
A22: Día 1 | B22: =SUMIFS('Costos por día'!$I$5:$I$61,'Costos por día'!$A$5:$A$61,A22) -> 6572 | C22: =SUMIFS('Costos por día'!$K$5:$K$61,'Costos por día'!$A$5:$A$61,A22) -> 15285.2 | D22: =IF($B$5=0,0,B22/$B$5) -> 1314.4 | E22: =IF($C$5=0,0,C22/$C$5) -> 1019.0133
A23: Día 2 | B23: =SUMIFS('Costos por día'!$I$5:$I$61,'Costos por día'!$A$5:$A$61,A23) -> 21081.259 | C23: =SUMIFS('Costos por día'!$K$5:$K$61,'Costos por día'!$A$5:$A$61,A23) -> 55791.977 | D23: =IF($B$5=0,0,B23/$B$5) -> 4216.2518 | E23: =IF($C$5=0,0,C23/$C$5) -> 3719.4651
A24: Día 3 | B24: =SUMIFS('Costos por día'!$I$5:$I$61,'Costos por día'!$A$5:$A$61,A24) -> 4791.2 | C24: =SUMIFS('Costos por día'!$K$5:$K$61,'Costos por día'!$A$5:$A$61,A24) -> 7653.2 | D24: =IF($B$5=0,0,B24/$B$5) -> 958.24 | E24: =IF($C$5=0,0,C24/$C$5) -> 510.21333
A25: Día 4 | B25: =SUMIFS('Costos por día'!$I$5:$I$61,'Costos por día'!$A$5:$A$61,A25) -> 11791.44 | C25: =SUMIFS('Costos por día'!$K$5:$K$61,'Costos por día'!$A$5:$A$61,A25) -> 24235.84 | D25: =IF($B$5=0,0,B25/$B$5) -> 2358.288 | E25: =IF($C$5=0,0,C25/$C$5) -> 1615.7227
A26: Día 5 | B26: =SUMIFS('Costos por día'!$I$5:$I$61,'Costos por día'!$A$5:$A$61,A26) -> 4483.8 | C26: =SUMIFS('Costos por día'!$K$5:$K$61,'Costos por día'!$A$5:$A$61,A26) -> 10525.8 | D26: =IF($B$5=0,0,B26/$B$5) -> 896.76 | E26: =IF($C$5=0,0,C26/$C$5) -> 701.72
A27: Día 6 | B27: =SUMIFS('Costos por día'!$I$5:$I$61,'Costos por día'!$A$5:$A$61,A27) -> 12126.4 | C27: =SUMIFS('Costos por día'!$K$5:$K$61,'Costos por día'!$A$5:$A$61,A27) -> 29574 | D27: =IF($B$5=0,0,B27/$B$5) -> 2425.28 | E27: =IF($C$5=0,0,C27/$C$5) -> 1971.6
A28: Día 7 | B28: =SUMIFS('Costos por día'!$I$5:$I$61,'Costos por día'!$A$5:$A$61,A28) -> 1017.6 | C28: =SUMIFS('Costos por día'!$K$5:$K$61,'Costos por día'!$A$5:$A$61,A28) -> 2098.8 | D28: =IF($B$5=0,0,B28/$B$5) -> 203.52 | E28: =IF($C$5=0,0,C28/$C$5) -> 139.92
A29: Total directo | B29: =SUM(B20:B28) -> 86384.679 | C29: =SUM(C20:C28) -> 193175.4 | D29: =SUM(D20:D28) -> 17276.936 | E29: =SUM(E20:E28) -> 12878.36
A31: Desglose por rubro
A32: Rubro | B32: Escenario 1 | C32: Escenario 2
A33: Vuelos | B33: =SUMIFS('Costos por día'!$I$5:$I$61,'Costos por día'!$C$5:$C$61,"Vuelo*") -> 9752 | C33: =SUMIFS('Costos por día'!$K$5:$K$61,'Costos por día'!$C$5:$C$61,"Vuelo*") -> 21942
A34: Hoteles | B34: =SUMIFS('Costos por día'!$I$5:$I$61,'Costos por día'!$C$5:$C$61,"*habitaci*") -> 13334.8 | C34: =SUMIFS('Costos por día'!$K$5:$K$61,'Costos por día'!$C$5:$C$61,"*habitaci*") -> 29234.8
A35: Autos clásicos (alquiler, seguro, combustible) | B35: =SUMIFS('Costos por día'!$I$5:$I$61,'Costos por día'!$C$5:$C$61,"*auto*") -> 17222.859 | C35: =SUMIFS('Costos por día'!$K$5:$K$61,'Costos por día'!$C$5:$C$61,"*auto*") -> 48488.577
A36: Comidas | B36: =SUMIFS('Costos por día'!$I$5:$I$61,'Costos por día'!$C$5:$C$61,"Desayuno*") -> 1780.8 | C36: =SUMIFS('Costos por día'!$K$5:$K$61,'Costos por día'!$C$5:$C$61,"Desayuno*") -> 4006.8
A37: Cenas y almuerzos | B37: =SUMIFS('Costos por día'!$I$5:$I$61,'Costos por día'!$C$5:$C$61,"Cena*") -> 5936 | C37: =SUMIFS('Costos por día'!$K$5:$K$61,'Costos por día'!$C$5:$C$61,"Cena*") -> 13356
A38: Almuerzos | B38: =SUMIFS('Costos por día'!$I$5:$I$61,'Costos por día'!$C$5:$C$61,"Almuerzo*") -> 2484.64 | C38: =SUMIFS('Costos por día'!$K$5:$K$61,'Costos por día'!$C$5:$C$61,"Almuerzo*") -> 5590.44
A39: Helicóptero | B39: =SUMIFS('Costos por día'!$I$5:$I$61,'Costos por día'!$C$5:$C$61,"Helic*") -> 2283.24 | C39: =SUMIFS('Costos por día'!$K$5:$K$61,'Costos por día'!$C$5:$C$61,"Helic*") -> 6088.64
A40: Pista | B40: =SUMIFS('Costos por día'!$I$5:$I$61,'Costos por día'!$C$5:$C$61,"Experiencia de pista*") -> 4770 | C40: =SUMIFS('Costos por día'!$K$5:$K$61,'Costos por día'!$C$5:$C$61,"Experiencia de pista*") -> 12720
A41: Traslados | B41: =SUMIFS('Costos por día'!$I$5:$I$61,'Costos por día'!$C$5:$C$61,"*sprinter*") -> 3127 | C41: =SUMIFS('Costos por día'!$K$5:$K$61,'Costos por día'!$C$5:$C$61,"*sprinter*") -> 6254
A42: (Los rubros se agrupan por el nombre de la actividad; las categorías no son exhaustivas ni excluyentes)

Sheet Margen y rentabilidad
A1: Margen y rentabilidad a USD 30.000 por persona
A2: Ingresos = participantes × precio. Costos desde 'Escenarios 5 vs 15'. Upgrade business y 'O' se venden como extras con margen propio.
A4: Concepto | B4: Escenario 1 (5 pax) | C4: Escenario 2 (15 pax) | D4: Notas
A5: Participantes | B5: ='Escenarios 5 vs 15'!B5 -> 5 | C5: ='Escenarios 5 vs 15'!C5 -> 15
A6: Precio por persona | B6: ='Supuestos y fuentes'!$C$8 -> 30000 | C6: ='Supuestos y fuentes'!$C$8 -> 30000
A7: INGRESOS | B7: =B5*B6 -> 150000 | C7: =C5*C6 -> 450000
A8: Costos fijos | B8: ='Escenarios 5 vs 15'!B8 -> 24639.7 | C8: ='Escenarios 5 vs 15'!C8 -> 27766.7
A9: Costos variables | B9: ='Escenarios 5 vs 15'!B9 -> 61744.979 | C9: ='Escenarios 5 vs 15'!C9 -> 165408.7
A10: Contingencia + costos financieros | B10: ='Escenarios 5 vs 15'!B11+'Escenarios 5 vs 15'!B12 -> 11410.774 | C10: ='Escenarios 5 vs 15'!C11+'Escenarios 5 vs 15'!C12 -> 28954.032
A11: COSTO TOTAL | B11: =B8+B9+B10 -> 97795.453 | C11: =C8+C9+C10 -> 222129.43
A12: MARGEN BRUTO (USD) | B12: =B7-B11 -> 52204.547 | C12: =C7-C11 -> 227870.57
A13: Margen bruto (%) | B13: =IF(B7=0,0,B12/B7) -> 0.34803031 | C13: =IF(C7=0,0,C12/C7) -> 0.50637905
A14: Margen por participante | B14: =IF(B5=0,0,B12/B5) -> 10440.909 | C14: =IF(C5=0,0,C12/C5) -> 15191.371
A15: Costo variable por participante (incl. contingencia y financieros) | B15: =IF(B5=0,0,(B9+B10)/B5) -> 14631.151 | C15: =IF(C5=0,0,(C9+C10)/C5) -> 12957.515
A16: Contribución por participante (precio − variable) | B16: =B6-B15 -> 15368.849 | C16: =C6-C15 -> 17042.485
A17: Punto de equilibrio (participantes) | B17: =IF(B16<=0,"n/a",ROUNDUP(B8/B16,1)) -> 1.7 | C17: =IF(C16<=0,"n/a",ROUNDUP(C8/C16,1)) -> 1.7 | D17: Participantes necesarios para cubrir los costos fijos (los fijos cambian poco entre escenarios)
A19: Extras opcionales (se venden aparte, margen adicional)
A20: Extra | B20: Costo | C20: Precio sugerido | D20: Margen unitario
A21: Upgrade a business EZE–LAS | B21: ='Supuestos y fuentes'!$C$17-'Supuestos y fuentes'!$C$16 -> 2850 | C21: ='Supuestos y fuentes'!$C$83 -> 3277.5 | D21: =C21-B21 -> 427.5
A22: Cirque du Soleil 'O' (categoría buena) | B22: ='Supuestos y fuentes'!$C$66 -> 250 | C22: ='Supuestos y fuentes'!$C$66*1.2 -> 300 | D22: =C22-B22 -> 50
A23: Copiloto acompañante (comparte auto y habitación doble) | B23: =('Supuestos y fuentes'!$C$16+'Supuestos y fuentes'!$C$18*'Supuestos y fuentes'!$C$19+'Supuestos y fuentes'!$C$73+'Supuestos y fuentes'!$C$61+'Supuestos y fuentes'!$C$65+'Supuestos y fuentes'!$C$54+'Supuestos y fuentes'!$C$64+'Supuestos y fuentes'!$C$56+'Supuestos y fuentes'!$C$60+'Supuestos y fuentes'!$C$39*7+'Supuestos y fuentes'!$C$40+'Supuestos y fuentes'!$C$41+'Supuestos y fuentes'!$C$42+'Supuestos y fuentes'!$C$43+'Supuestos y fuentes'!$C$44+'Supuestos y fuentes'!$C$45+'Supuestos y fuentes'!$C$46+'Supuestos y fuentes'!$C$47+'Supuestos y fuentes'!$C$48+'Supuestos y fuentes'!$C$49+'Supuestos y fuentes'!$C$50+'Supuestos y fuentes'!$C$51+'Supuestos y fuentes'!$C$52)*(1+'Supuestos y fuentes'!$C$11) -> 4494.4 | C23: =ROUND(B23*1.6,-2) -> 7200 | D23: =C23-B23 -> 2705.6
A24: El copiloto no suma auto ni habitación (comparte), por eso su costo es mucho menor que el de un participante pleno: precio sugerido ≈ costo × 1,6.
A26: Sensibilidad: margen bruto (USD) según precio y cantidad de participantes
A27: Usa el costo fijo del esc. 2 y el costo variable por participante del esc. 2 (hoja Escenarios); contingencia y financieros incluidos.
A28: Participantes \ Precio | B28: 24000 | C28: 27000 | D28: 30000 | E28: 33000 | F28: 36000
A29: 4 | B29: =$A29*B$28-('Escenarios 5 vs 15'!$C$8*(1+'Supuestos y fuentes'!$C$12))-$A29*('Escenarios 5 vs 15'!$C$9/'Escenarios 5 vs 15'!$C$5*(1+'Supuestos y fuentes'!$C$12))-$A29*B$28*'Supuestos y fuentes'!$C$13 -> 15494.259 | C29: =$A29*C$28-('Escenarios 5 vs 15'!$C$8*(1+'Supuestos y fuentes'!$C$12))-$A29*('Escenarios 5 vs 15'!$C$9/'Escenarios 5 vs 15'!$C$5*(1+'Supuestos y fuentes'!$C$12))-$A29*C$28*'Supuestos y fuentes'!$C$13 -> 27134.259 | D29: =$A29*D$28-('Escenarios 5 vs 15'!$C$8*(1+'Supuestos y fuentes'!$C$12))-$A29*('Escenarios 5 vs 15'!$C$9/'Escenarios 5 vs 15'!$C$5*(1+'Supuestos y fuentes'!$C$12))-$A29*D$28*'Supuestos y fuentes'!$C$13 -> 38774.259 | E29: =$A29*E$28-('Escenarios 5 vs 15'!$C$8*(1+'Supuestos y fuentes'!$C$12))-$A29*('Escenarios 5 vs 15'!$C$9/'Escenarios 5 vs 15'!$C$5*(1+'Supuestos y fuentes'!$C$12))-$A29*E$28*'Supuestos y fuentes'!$C$13 -> 50414.259 | F29: =$A29*F$28-('Escenarios 5 vs 15'!$C$8*(1+'Supuestos y fuentes'!$C$12))-$A29*('Escenarios 5 vs 15'!$C$9/'Escenarios 5 vs 15'!$C$5*(1+'Supuestos y fuentes'!$C$12))-$A29*F$28*'Supuestos y fuentes'!$C$13 -> 62054.259
A30: 5 | B30: =$A30*B$28-('Escenarios 5 vs 15'!$C$8*(1+'Supuestos y fuentes'!$C$12))-$A30*('Escenarios 5 vs 15'!$C$9/'Escenarios 5 vs 15'!$C$5*(1+'Supuestos y fuentes'!$C$12))-$A30*B$28*'Supuestos y fuentes'!$C$13 -> 26864.833 | C30: =$A30*C$28-('Escenarios 5 vs 15'!$C$8*(1+'Supuestos y fuentes'!$C$12))-$A30*('Escenarios 5 vs 15'!$C$9/'Escenarios 5 vs 15'!$C$5*(1+'Supuestos y fuentes'!$C$12))-$A30*C$28*'Supuestos y fuentes'!$C$13 -> 41414.833 | D30: =$A30*D$28-('Escenarios 5 vs 15'!$C$8*(1+'Supuestos y fuentes'!$C$12))-$A30*('Escenarios 5 vs 15'!$C$9/'Escenarios 5 vs 15'!$C$5*(1+'Supuestos y fuentes'!$C$12))-$A30*D$28*'Supuestos y fuentes'!$C$13 -> 55964.833 | E30: =$A30*E$28-('Escenarios 5 vs 15'!$C$8*(1+'Supuestos y fuentes'!$C$12))-$A30*('Escenarios 5 vs 15'!$C$9/'Escenarios 5 vs 15'!$C$5*(1+'Supuestos y fuentes'!$C$12))-$A30*E$28*'Supuestos y fuentes'!$C$13 -> 70514.833 | F30: =$A30*F$28-('Escenarios 5 vs 15'!$C$8*(1+'Supuestos y fuentes'!$C$12))-$A30*('Escenarios 5 vs 15'!$C$9/'Escenarios 5 vs 15'!$C$5*(1+'Supuestos y fuentes'!$C$12))-$A30*F$28*'Supuestos y fuentes'!$C$13 -> 85064.833
A31: 8 | B31: =$A31*B$28-('Escenarios 5 vs 15'!$C$8*(1+'Supuestos y fuentes'!$C$12))-$A31*('Escenarios 5 vs 15'!$C$9/'Escenarios 5 vs 15'!$C$5*(1+'Supuestos y fuentes'!$C$12))-$A31*B$28*'Supuestos y fuentes'!$C$13 -> 60976.555 | C31: =$A31*C$28-('Escenarios 5 vs 15'!$C$8*(1+'Supuestos y fuentes'!$C$12))-$A31*('Escenarios 5 vs 15'!$C$9/'Escenarios 5 vs 15'!$C$5*(1+'Supuestos y fuentes'!$C$12))-$A31*C$28*'Supuestos y fuentes'!$C$13 -> 84256.555 | D31: =$A31*D$28-('Escenarios 5 vs 15'!$C$8*(1+'Supuestos y fuentes'!$C$12))-$A31*('Escenarios 5 vs 15'!$C$9/'Escenarios 5 vs 15'!$C$5*(1+'Supuestos y fuentes'!$C$12))-$A31*D$28*'Supuestos y fuentes'!$C$13 -> 107536.55 | E31: =$A31*E$28-('Escenarios 5 vs 15'!$C$8*(1+'Supuestos y fuentes'!$C$12))-$A31*('Escenarios 5 vs 15'!$C$9/'Escenarios 5 vs 15'!$C$5*(1+'Supuestos y fuentes'!$C$12))-$A31*E$28*'Supuestos y fuentes'!$C$13 -> 130816.55 | F31: =$A31*F$28-('Escenarios 5 vs 15'!$C$8*(1+'Supuestos y fuentes'!$C$12))-$A31*('Escenarios 5 vs 15'!$C$9/'Escenarios 5 vs 15'!$C$5*(1+'Supuestos y fuentes'!$C$12))-$A31*F$28*'Supuestos y fuentes'!$C$13 -> 154096.55
A32: 10 | B32: =$A32*B$28-('Escenarios 5 vs 15'!$C$8*(1+'Supuestos y fuentes'!$C$12))-$A32*('Escenarios 5 vs 15'!$C$9/'Escenarios 5 vs 15'!$C$5*(1+'Supuestos y fuentes'!$C$12))-$A32*B$28*'Supuestos y fuentes'!$C$13 -> 83717.702 | C32: =$A32*C$28-('Escenarios 5 vs 15'!$C$8*(1+'Supuestos y fuentes'!$C$12))-$A32*('Escenarios 5 vs 15'!$C$9/'Escenarios 5 vs 15'!$C$5*(1+'Supuestos y fuentes'!$C$12))-$A32*C$28*'Supuestos y fuentes'!$C$13 -> 112817.7 | D32: =$A32*D$28-('Escenarios 5 vs 15'!$C$8*(1+'Supuestos y fuentes'!$C$12))-$A32*('Escenarios 5 vs 15'!$C$9/'Escenarios 5 vs 15'!$C$5*(1+'Supuestos y fuentes'!$C$12))-$A32*D$28*'Supuestos y fuentes'!$C$13 -> 141917.7 | E32: =$A32*E$28-('Escenarios 5 vs 15'!$C$8*(1+'Supuestos y fuentes'!$C$12))-$A32*('Escenarios 5 vs 15'!$C$9/'Escenarios 5 vs 15'!$C$5*(1+'Supuestos y fuentes'!$C$12))-$A32*E$28*'Supuestos y fuentes'!$C$13 -> 171017.7 | F32: =$A32*F$28-('Escenarios 5 vs 15'!$C$8*(1+'Supuestos y fuentes'!$C$12))-$A32*('Escenarios 5 vs 15'!$C$9/'Escenarios 5 vs 15'!$C$5*(1+'Supuestos y fuentes'!$C$12))-$A32*F$28*'Supuestos y fuentes'!$C$13 -> 200117.7
A33: 12 | B33: =$A33*B$28-('Escenarios 5 vs 15'!$C$8*(1+'Supuestos y fuentes'!$C$12))-$A33*('Escenarios 5 vs 15'!$C$9/'Escenarios 5 vs 15'!$C$5*(1+'Supuestos y fuentes'!$C$12))-$A33*B$28*'Supuestos y fuentes'!$C$13 -> 106458.85 | C33: =$A33*C$28-('Escenarios 5 vs 15'!$C$8*(1+'Supuestos y fuentes'!$C$12))-$A33*('Escenarios 5 vs 15'!$C$9/'Escenarios 5 vs 15'!$C$5*(1+'Supuestos y fuentes'!$C$12))-$A33*C$28*'Supuestos y fuentes'!$C$13 -> 141378.85 | D33: =$A33*D$28-('Escenarios 5 vs 15'!$C$8*(1+'Supuestos y fuentes'!$C$12))-$A33*('Escenarios 5 vs 15'!$C$9/'Escenarios 5 vs 15'!$C$5*(1+'Supuestos y fuentes'!$C$12))-$A33*D$28*'Supuestos y fuentes'!$C$13 -> 176298.85 | E33: =$A33*E$28-('Escenarios 5 vs 15'!$C$8*(1+'Supuestos y fuentes'!$C$12))-$A33*('Escenarios 5 vs 15'!$C$9/'Escenarios 5 vs 15'!$C$5*(1+'Supuestos y fuentes'!$C$12))-$A33*E$28*'Supuestos y fuentes'!$C$13 -> 211218.85 | F33: =$A33*F$28-('Escenarios 5 vs 15'!$C$8*(1+'Supuestos y fuentes'!$C$12))-$A33*('Escenarios 5 vs 15'!$C$9/'Escenarios 5 vs 15'!$C$5*(1+'Supuestos y fuentes'!$C$12))-$A33*F$28*'Supuestos y fuentes'!$C$13 -> 246138.85
A34: 15 | B34: =$A34*B$28-('Escenarios 5 vs 15'!$C$8*(1+'Supuestos y fuentes'!$C$12))-$A34*('Escenarios 5 vs 15'!$C$9/'Escenarios 5 vs 15'!$C$5*(1+'Supuestos y fuentes'!$C$12))-$A34*B$28*'Supuestos y fuentes'!$C$13 -> 140570.57 | C34: =$A34*C$28-('Escenarios 5 vs 15'!$C$8*(1+'Supuestos y fuentes'!$C$12))-$A34*('Escenarios 5 vs 15'!$C$9/'Escenarios 5 vs 15'!$C$5*(1+'Supuestos y fuentes'!$C$12))-$A34*C$28*'Supuestos y fuentes'!$C$13 -> 184220.57 | D34: =$A34*D$28-('Escenarios 5 vs 15'!$C$8*(1+'Supuestos y fuentes'!$C$12))-$A34*('Escenarios 5 vs 15'!$C$9/'Escenarios 5 vs 15'!$C$5*(1+'Supuestos y fuentes'!$C$12))-$A34*D$28*'Supuestos y fuentes'!$C$13 -> 227870.57 | E34: =$A34*E$28-('Escenarios 5 vs 15'!$C$8*(1+'Supuestos y fuentes'!$C$12))-$A34*('Escenarios 5 vs 15'!$C$9/'Escenarios 5 vs 15'!$C$5*(1+'Supuestos y fuentes'!$C$12))-$A34*E$28*'Supuestos y fuentes'!$C$13 -> 271520.57 | F34: =$A34*F$28-('Escenarios 5 vs 15'!$C$8*(1+'Supuestos y fuentes'!$C$12))-$A34*('Escenarios 5 vs 15'!$C$9/'Escenarios 5 vs 15'!$C$5*(1+'Supuestos y fuentes'!$C$12))-$A34*F$28*'Supuestos y fuentes'!$C$13 -> 315170.57
A35: 18 | B35: =$A35*B$28-('Escenarios 5 vs 15'!$C$8*(1+'Supuestos y fuentes'!$C$12))-$A35*('Escenarios 5 vs 15'!$C$9/'Escenarios 5 vs 15'!$C$5*(1+'Supuestos y fuentes'!$C$12))-$A35*B$28*'Supuestos y fuentes'!$C$13 -> 174682.29 | C35: =$A35*C$28-('Escenarios 5 vs 15'!$C$8*(1+'Supuestos y fuentes'!$C$12))-$A35*('Escenarios 5 vs 15'!$C$9/'Escenarios 5 vs 15'!$C$5*(1+'Supuestos y fuentes'!$C$12))-$A35*C$28*'Supuestos y fuentes'!$C$13 -> 227062.29 | D35: =$A35*D$28-('Escenarios 5 vs 15'!$C$8*(1+'Supuestos y fuentes'!$C$12))-$A35*('Escenarios 5 vs 15'!$C$9/'Escenarios 5 vs 15'!$C$5*(1+'Supuestos y fuentes'!$C$12))-$A35*D$28*'Supuestos y fuentes'!$C$13 -> 279442.29 | E35: =$A35*E$28-('Escenarios 5 vs 15'!$C$8*(1+'Supuestos y fuentes'!$C$12))-$A35*('Escenarios 5 vs 15'!$C$9/'Escenarios 5 vs 15'!$C$5*(1+'Supuestos y fuentes'!$C$12))-$A35*E$28*'Supuestos y fuentes'!$C$13 -> 331822.29 | F35: =$A35*F$28-('Escenarios 5 vs 15'!$C$8*(1+'Supuestos y fuentes'!$C$12))-$A35*('Escenarios 5 vs 15'!$C$9/'Escenarios 5 vs 15'!$C$5*(1+'Supuestos y fuentes'!$C$12))-$A35*F$28*'Supuestos y fuentes'!$C$13 -> 384202.29
A37: Sensibilidad: margen bruto (%)
A38: Participantes \ Precio | B38: 24000 | C38: 27000 | D38: 30000 | E38: 33000 | F38: 36000
A39: 4 | B39: =1-(('Escenarios 5 vs 15'!$C$8*(1+'Supuestos y fuentes'!$C$12))+$A39*('Escenarios 5 vs 15'!$C$9/'Escenarios 5 vs 15'!$C$5*(1+'Supuestos y fuentes'!$C$12))+$A39*B$38*'Supuestos y fuentes'!$C$13)/($A39*B$38) -> 0.16139853 | C39: =1-(('Escenarios 5 vs 15'!$C$8*(1+'Supuestos y fuentes'!$C$12))+$A39*('Escenarios 5 vs 15'!$C$9/'Escenarios 5 vs 15'!$C$5*(1+'Supuestos y fuentes'!$C$12))+$A39*C$38*'Supuestos y fuentes'!$C$13)/($A39*C$38) -> 0.25124314 | D39: =1-(('Escenarios 5 vs 15'!$C$8*(1+'Supuestos y fuentes'!$C$12))+$A39*('Escenarios 5 vs 15'!$C$9/'Escenarios 5 vs 15'!$C$5*(1+'Supuestos y fuentes'!$C$12))+$A39*D$38*'Supuestos y fuentes'!$C$13)/($A39*D$38) -> 0.32311883 | E39: =1-(('Escenarios 5 vs 15'!$C$8*(1+'Supuestos y fuentes'!$C$12))+$A39*('Escenarios 5 vs 15'!$C$9/'Escenarios 5 vs 15'!$C$5*(1+'Supuestos y fuentes'!$C$12))+$A39*E$38*'Supuestos y fuentes'!$C$13)/($A39*E$38) -> 0.38192621 | F39: =1-(('Escenarios 5 vs 15'!$C$8*(1+'Supuestos y fuentes'!$C$12))+$A39*('Escenarios 5 vs 15'!$C$9/'Escenarios 5 vs 15'!$C$5*(1+'Supuestos y fuentes'!$C$12))+$A39*F$38*'Supuestos y fuentes'!$C$13)/($A39*F$38) -> 0.43093236
A40: 5 | B40: =1-(('Escenarios 5 vs 15'!$C$8*(1+'Supuestos y fuentes'!$C$12))+$A40*('Escenarios 5 vs 15'!$C$9/'Escenarios 5 vs 15'!$C$5*(1+'Supuestos y fuentes'!$C$12))+$A40*B$38*'Supuestos y fuentes'!$C$13)/($A40*B$38) -> 0.22387361 | C40: =1-(('Escenarios 5 vs 15'!$C$8*(1+'Supuestos y fuentes'!$C$12))+$A40*('Escenarios 5 vs 15'!$C$9/'Escenarios 5 vs 15'!$C$5*(1+'Supuestos y fuentes'!$C$12))+$A40*C$38*'Supuestos y fuentes'!$C$13)/($A40*C$38) -> 0.30677654 | D40: =1-(('Escenarios 5 vs 15'!$C$8*(1+'Supuestos y fuentes'!$C$12))+$A40*('Escenarios 5 vs 15'!$C$9/'Escenarios 5 vs 15'!$C$5*(1+'Supuestos y fuentes'!$C$12))+$A40*D$38*'Supuestos y fuentes'!$C$13)/($A40*D$38) -> 0.37309889 | E40: =1-(('Escenarios 5 vs 15'!$C$8*(1+'Supuestos y fuentes'!$C$12))+$A40*('Escenarios 5 vs 15'!$C$9/'Escenarios 5 vs 15'!$C$5*(1+'Supuestos y fuentes'!$C$12))+$A40*E$38*'Supuestos y fuentes'!$C$13)/($A40*E$38) -> 0.42736263 | F40: =1-(('Escenarios 5 vs 15'!$C$8*(1+'Supuestos y fuentes'!$C$12))+$A40*('Escenarios 5 vs 15'!$C$9/'Escenarios 5 vs 15'!$C$5*(1+'Supuestos y fuentes'!$C$12))+$A40*F$38*'Supuestos y fuentes'!$C$13)/($A40*F$38) -> 0.47258241
A41: 8 | B41: =1-(('Escenarios 5 vs 15'!$C$8*(1+'Supuestos y fuentes'!$C$12))+$A41*('Escenarios 5 vs 15'!$C$9/'Escenarios 5 vs 15'!$C$5*(1+'Supuestos y fuentes'!$C$12))+$A41*B$38*'Supuestos y fuentes'!$C$13)/($A41*B$38) -> 0.31758622 | C41: =1-(('Escenarios 5 vs 15'!$C$8*(1+'Supuestos y fuentes'!$C$12))+$A41*('Escenarios 5 vs 15'!$C$9/'Escenarios 5 vs 15'!$C$5*(1+'Supuestos y fuentes'!$C$12))+$A41*C$38*'Supuestos y fuentes'!$C$13)/($A41*C$38) -> 0.39007664 | D41: =1-(('Escenarios 5 vs 15'!$C$8*(1+'Supuestos y fuentes'!$C$12))+$A41*('Escenarios 5 vs 15'!$C$9/'Escenarios 5 vs 15'!$C$5*(1+'Supuestos y fuentes'!$C$12))+$A41*D$38*'Supuestos y fuentes'!$C$13)/($A41*D$38) -> 0.44806898 | E41: =1-(('Escenarios 5 vs 15'!$C$8*(1+'Supuestos y fuentes'!$C$12))+$A41*('Escenarios 5 vs 15'!$C$9/'Escenarios 5 vs 15'!$C$5*(1+'Supuestos y fuentes'!$C$12))+$A41*E$38*'Supuestos y fuentes'!$C$13)/($A41*E$38) -> 0.49551725 | F41: =1-(('Escenarios 5 vs 15'!$C$8*(1+'Supuestos y fuentes'!$C$12))+$A41*('Escenarios 5 vs 15'!$C$9/'Escenarios 5 vs 15'!$C$5*(1+'Supuestos y fuentes'!$C$12))+$A41*F$38*'Supuestos y fuentes'!$C$13)/($A41*F$38) -> 0.53505748
A42: 10 | B42: =1-(('Escenarios 5 vs 15'!$C$8*(1+'Supuestos y fuentes'!$C$12))+$A42*('Escenarios 5 vs 15'!$C$9/'Escenarios 5 vs 15'!$C$5*(1+'Supuestos y fuentes'!$C$12))+$A42*B$38*'Supuestos y fuentes'!$C$13)/($A42*B$38) -> 0.34882376 | C42: =1-(('Escenarios 5 vs 15'!$C$8*(1+'Supuestos y fuentes'!$C$12))+$A42*('Escenarios 5 vs 15'!$C$9/'Escenarios 5 vs 15'!$C$5*(1+'Supuestos y fuentes'!$C$12))+$A42*C$38*'Supuestos y fuentes'!$C$13)/($A42*C$38) -> 0.41784334 | D42: =1-(('Escenarios 5 vs 15'!$C$8*(1+'Supuestos y fuentes'!$C$12))+$A42*('Escenarios 5 vs 15'!$C$9/'Escenarios 5 vs 15'!$C$5*(1+'Supuestos y fuentes'!$C$12))+$A42*D$38*'Supuestos y fuentes'!$C$13)/($A42*D$38) -> 0.47305901 | E42: =1-(('Escenarios 5 vs 15'!$C$8*(1+'Supuestos y fuentes'!$C$12))+$A42*('Escenarios 5 vs 15'!$C$9/'Escenarios 5 vs 15'!$C$5*(1+'Supuestos y fuentes'!$C$12))+$A42*E$38*'Supuestos y fuentes'!$C$13)/($A42*E$38) -> 0.51823546 | F42: =1-(('Escenarios 5 vs 15'!$C$8*(1+'Supuestos y fuentes'!$C$12))+$A42*('Escenarios 5 vs 15'!$C$9/'Escenarios 5 vs 15'!$C$5*(1+'Supuestos y fuentes'!$C$12))+$A42*F$38*'Supuestos y fuentes'!$C$13)/($A42*F$38) -> 0.55588251
A43: 12 | B43: =1-(('Escenarios 5 vs 15'!$C$8*(1+'Supuestos y fuentes'!$C$12))+$A43*('Escenarios 5 vs 15'!$C$9/'Escenarios 5 vs 15'!$C$5*(1+'Supuestos y fuentes'!$C$12))+$A43*B$38*'Supuestos y fuentes'!$C$13)/($A43*B$38) -> 0.36964878 | C43: =1-(('Escenarios 5 vs 15'!$C$8*(1+'Supuestos y fuentes'!$C$12))+$A43*('Escenarios 5 vs 15'!$C$9/'Escenarios 5 vs 15'!$C$5*(1+'Supuestos y fuentes'!$C$12))+$A43*C$38*'Supuestos y fuentes'!$C$13)/($A43*C$38) -> 0.43635448 | D43: =1-(('Escenarios 5 vs 15'!$C$8*(1+'Supuestos y fuentes'!$C$12))+$A43*('Escenarios 5 vs 15'!$C$9/'Escenarios 5 vs 15'!$C$5*(1+'Supuestos y fuentes'!$C$12))+$A43*D$38*'Supuestos y fuentes'!$C$13)/($A43*D$38) -> 0.48971903 | E43: =1-(('Escenarios 5 vs 15'!$C$8*(1+'Supuestos y fuentes'!$C$12))+$A43*('Escenarios 5 vs 15'!$C$9/'Escenarios 5 vs 15'!$C$5*(1+'Supuestos y fuentes'!$C$12))+$A43*E$38*'Supuestos y fuentes'!$C$13)/($A43*E$38) -> 0.53338093 | F43: =1-(('Escenarios 5 vs 15'!$C$8*(1+'Supuestos y fuentes'!$C$12))+$A43*('Escenarios 5 vs 15'!$C$9/'Escenarios 5 vs 15'!$C$5*(1+'Supuestos y fuentes'!$C$12))+$A43*F$38*'Supuestos y fuentes'!$C$13)/($A43*F$38) -> 0.56976586
A44: 15 | B44: =1-(('Escenarios 5 vs 15'!$C$8*(1+'Supuestos y fuentes'!$C$12))+$A44*('Escenarios 5 vs 15'!$C$9/'Escenarios 5 vs 15'!$C$5*(1+'Supuestos y fuentes'!$C$12))+$A44*B$38*'Supuestos y fuentes'!$C$13)/($A44*B$38) -> 0.39047381 | C44: =1-(('Escenarios 5 vs 15'!$C$8*(1+'Supuestos y fuentes'!$C$12))+$A44*('Escenarios 5 vs 15'!$C$9/'Escenarios 5 vs 15'!$C$5*(1+'Supuestos y fuentes'!$C$12))+$A44*C$38*'Supuestos y fuentes'!$C$13)/($A44*C$38) -> 0.45486561 | D44: =1-(('Escenarios 5 vs 15'!$C$8*(1+'Supuestos y fuentes'!$C$12))+$A44*('Escenarios 5 vs 15'!$C$9/'Escenarios 5 vs 15'!$C$5*(1+'Supuestos y fuentes'!$C$12))+$A44*D$38*'Supuestos y fuentes'!$C$13)/($A44*D$38) -> 0.50637905 | E44: =1-(('Escenarios 5 vs 15'!$C$8*(1+'Supuestos y fuentes'!$C$12))+$A44*('Escenarios 5 vs 15'!$C$9/'Escenarios 5 vs 15'!$C$5*(1+'Supuestos y fuentes'!$C$12))+$A44*E$38*'Supuestos y fuentes'!$C$13)/($A44*E$38) -> 0.54852641 | F44: =1-(('Escenarios 5 vs 15'!$C$8*(1+'Supuestos y fuentes'!$C$12))+$A44*('Escenarios 5 vs 15'!$C$9/'Escenarios 5 vs 15'!$C$5*(1+'Supuestos y fuentes'!$C$12))+$A44*F$38*'Supuestos y fuentes'!$C$13)/($A44*F$38) -> 0.58364921
...

Sheet Supuestos y fuentes
A1: Travesía Ruta 66 — Supuestos y fuentes
A2: Celdas en AZUL sobre fondo amarillo = entradas editables. Todo lo demás se recalcula. Precios en USD, relevados oct-2026 para un viaje en nov-2027: aplicar el ajuste de inflación de la fila 'Ajuste de precios a 2027'.
A4: Clave | B4: Supuesto | C4: Valor | D4: Unidad | E4: Fuente / justificación | F4: URL
A5: ESCENARIO Y PRECIO
A6: PAX_A | B6: Participantes — escenario 1 (primer viaje) | C6: 5 | D6: personas | E6: Definido por Fantasma Garage
A7: PAX_B | B7: Participantes — escenario 2 (a partir del 2º viaje) | C7: 15 | D7: personas | E7: Definido por Fantasma Garage
A8: PRECIO | B8: Precio de venta por persona | C8: 30000 | D8: USD/persona | E8: Precio objetivo definido por Fantasma Garage
A9: STAFF | B9: Staff que viaja desde Argentina (Javier, Jorge, Alejandro) | C9: 3 | D9: personas | E9: Definido por Fantasma Garage — turista, sin auto propio, rotan como acompañantes
A10: STAFF_ROOMS | B10: Habitaciones de staff por noche | C10: 2 | D10: habitaciones | E10: Supuesto: Javier en single, Jorge y Alejandro comparten. Cambiar a 3 si van en singles.
A11: INFL | B11: Ajuste de precios a nov-2027 (inflación USD + temporada SEMA) | C11: 0.06 | D11: % | E11: Supuesto: ~3% inflación anual EE.UU. x1 año + colchón por SEMA (semana de mayor demanda hotelera del año en Las Vegas)
A12: CONTING | B12: Contingencia sobre costos directos | C12: 0.08 | D12: % | E12: Supuesto de buenas prácticas para viajes a medida con proveedores a confirmar
A13: FIN | B13: Costos financieros / pasarela de cobro sobre ingresos | C13: 0.03 | D13: % | E13: Supuesto: comisión de cobro internacional (tarjeta/transferencia) + diferencia de cambio
A14: INCL_O | B14: ¿Incluir Cirque du Soleil 'O' en el precio? (1 = sí, 0 = opcional aparte) | C14: 0 | D14: 1/0 | E14: Decisión Fantasma Garage: opcional, no incluido
A15: VUELOS Y SEGUROS
A16: VUELO_ECO | B16: Vuelo EZE–LAS ida y vuelta, turista | C16: 1150 | D16: USD/persona | E16: KAYAK: promedio 12 meses USD 984, rango típico 886–1.223; ofertas nov. 1.001–1.151. Se toma el techo del rango (temporada SEMA, 1 escala) | F16: https://www.kayak.com/flight-routes/Buenos-Aires-Ministro-Pistarini-EZE/Las-Vegas-McCarran-LAS
A17: VUELO_BIZ | B17: Vuelo EZE–LAS ida y vuelta, business (solo para cotizar el upgrade opcional) | C17: 4000 | D17: USD/persona | E17: KAYAK: promedio business EE.UU.–Buenos Aires USD 3.988; 'buen precio' ≤ 3.390 | F17: https://www.kayak.com/flight-routes/Business-Class-United-States-US0/Buenos-Aires-BUE.bc.ksp
A18: SEG_VIAJE | B18: Asistencia al viajero / seguro médico EE.UU. | C18: 9 | D18: USD/persona/día | E18: Supuesto a partir de cotizaciones Assist Card (≈ AR$ 9.700/día en ene-2026 con promo); cotizar plan con cobertura ≥ USD 150.000 | F18: https://www.assistcard.com/ar/seguro-de-viaje-estados-unidos
A19: DIAS_SEG | B19: Días de cobertura (jue 4 → jue 11 + viaje) | C19: 9 | D19: días | E19: Itinerario
A20: AUTOS CLÁSICOS Y COMBUSTIBLE
A21: AUTO_DIA | B21: Alquiler auto clásico (Mustang '65–'69, Chevelle '68, Firebird, GS) por día | C21: 475 | D21: USD/auto/día | E21: 777 Exotics Las Vegas: 1965 Mustang Conv. USD 449/día, 1966 GT350 y 1969 Mustang USD 499/día, '68 Chevelle USD 449/día. Ride Free (1969 Camaro) USD 499/día, 150 mi/día incluidas | F21: https://777exoticslv.com/classic-car-rentals/
A22: AUTO_DIAS | B22: Días de alquiler (sáb 6 → mié 10) | C22: 5 | D22: días | E22: Itinerario: entrega sábado, devolución miércoles
A23: AUTO_SEG | B23: Seguro por auto (daño + responsabilidad civil suplementaria) | C23: 45 | D23: USD/auto/día | E23: Bonzah/RentalCover: daño USD 7–15/día; se suma responsabilidad suplementaria hasta USD 1M y recargo por vehículo de colección. Confirmar con el rentador (exigen póliza primaria) | F23: https://www.thetraveler.org/bonzah-vs-rentalcover-which-rental-car-insurance-wins/
A24: AUTOS_PP | B24: Autos por participante | C24: 1 | D24: autos/persona | E24: Definido: un auto por persona (0,5 si viajan con copiloto)
A25: KM_TOTAL | B25: Kilómetros totales del recorrido por auto | C25: 1350 | D25: km | E25: Suma de tramos (ver hoja 'Costos por día'): LAS–Boulder City 42 km, Hoover 13, Boulder–Kingman 120, Kingman–Oatman ida/vuelta 90, Kingman–Seligman 140, Seligman–Williams 70, Williams–GC 95, GC–Peach Springs 225, Peach Springs–Kingman 80, Kingman–Valle de Fuego 245, VdF–LAS 90, Speedway ida/vuelta 60, margen 80 | F25: https://www.aaa.com/tripcanvas/roadtrip/route-66-western-arizona-road-trip-AA156
A26: MPG | B26: Consumo clásico V8 (millas por galón) | C26: 12 | D26: mpg | E26: Supuesto: muscle car V8 carburado 1965–1977, ruta mixta con montaña
A27: GAS | B27: Nafta regular (promedio NV/AZ) | C27: 5 | D27: USD/galón | E27: AAA oct-2026: Nevada USD 5,33 (Las Vegas 5,38), Arizona USD 4,55. Promedio ponderado por km | F27: https://www.fox5vegas.com/2026/10/22/aaa-nevada-data-shows-gas-prices-falling/
A28: APOYO_DIA | B28: Vehículo de apoyo (pickup F-150 / SUV grande) por día | C28: 95 | D28: USD/día | E28: KAYAK: pickups en Las Vegas promedio £44–51/día (~USD 60–70), octubre el mes más caro (~£71 ≈ USD 95) | F28: https://www.kayak.co.uk/Las-Vegas-Pick-up-truck-Car-Hire.35107.cpk.ksp
A29: APOYO_DIAS | B29: Días vehículo de apoyo | C29: 7 | D29: días | E29: Jue 4 → jue 11 (también se usa para traslados cortos y equipaje)
A30: APOYO_EXTRA | B30: Herramientas, repuestos, aceite, combustible del vehículo de apoyo | C30: 900 | D30: USD fijo | E30: Supuesto: kit de ruta para 8 autos clásicos (correas, bujías, mangueras, batería de arranque, fluidos) + ~1.400 km de combustible del pickup
A31: HOTELES (precio por habitación y noche, impuestos y resort fee incluidos)
A32: H_VENETIAN | B32: The Venetian Resort — suite estándar (jue 4 y vie 5) | C32: 520 | D32: USD/hab/noche | E32: KAYAK: promedio dom–jue USD 360, vie–sáb USD 457 (suites 650 ft²) + resort fee USD 45 + 13,38% = USD 51,02/noche. Semana SEMA: tomar valor alto | F32: https://www.kayak.com/Las-Vegas-Hotels-The-Venetian-Resort-Las-Vegas.31420.ksp
A33: H_BOULDER | B33: Boulder Dam Hotel (histórico, 1933) — sáb 6 | C33: 160 | D33: USD/hab/noche | E33: KAYAK: USD 88–166/noche con cargos; promedio fin de semana USD 146. Hotel de 20 habitaciones: con 15 pax conviene reservar el hotel completo | F33: https://www.kayak.com/Boulder-City-Hotels-Boulder-Dam-Hotel.3239.ksp
A34: H_WILLIAMS | B34: Motel años 50 restaurado en Williams (El Rancho / The Lodge on Route 66) — dom 7 | C34: 140 | D34: USD/hab/noche | E34: KAYAK: El Rancho Motel USD 91–146/noche, octubre promedio USD 131 ('vibe sesentoso', en la Ruta 66). Se suma margen por bloqueo de habitaciones | F34: https://www.kayak.com/Williams-Hotels-El-Rancho-Motel.78717.ksp
A35: H_ELTOVAR | B35: El Tovar Hotel (1905, borde sur) — lun 8 | C35: 480 | D35: USD/hab/noche | E35: Xanterra: 'varios cientos de dólares por noche' + 6,9% impuesto; suites no siempre online. Reservas abren 13 meses antes → reservar en oct-2026 | F35: https://getcostidea.com/how-much-does-it-cost-to-stay-at-el-tovar-hotel-grand-canyon-rates-fees/
A36: H_CIRCA | B36: Circa Resort (Downtown, solo adultos, Fremont St.) — mar 9 | C36: 300 | D36: USD/hab/noche | E36: Resort fee USD 50 (Las Vegas Advisor) + tarifa estimada USD 250 (martes). Alternativa: Golden Nugget (fee USD 46) | F36: https://www.lasvegasadvisor.com/resort-fees-downtown/
A37: H_BELLAGIO | B37: Bellagio — Fountain View (mié 10, noche de cierre) | C37: 420 | D37: USD/hab/noche | E37: lasvegaswonders: Fountain View USD 229–299 entre semana + resort fee USD 55 + impuesto ≈ USD 62; valet USD 35/día | F37: https://lasvegaswonders.com/?p=8834
A38: COMIDAS (por persona, con impuestos y propina 18–20%)
A39: DESAYUNO | B39: Desayuno promedio | C39: 30 | D39: USD/persona | E39: Supuesto: desayuno en hotel/diner. Boulder Dam Hotel lo incluye
A40: CENA_VENETIAN | B40: Cena de bienvenida en The Venetian (Delmonico / Bouchon) | C40: 160 | D40: USD/persona | E40: Supuesto en línea con steakhouses premium del Strip: cortes USD 75–150 + guarniciones USD 18–24 (lasvegaswonders) | F40: https://lasvegaswonders.com/las-vegas-steakhouse-prices/
A41: CENA_HARDROCK | B41: Cena Hard Rock Café (menú 'Electric' 3 pasos) o Coyote Ugly | C41: 70 | D41: USD/persona | E41: Expedia: menú Electric USD 66,25 pp con impuestos y 18% propina | F41: https://www.expedia.com/things-to-do/comer-en-el-hard-rock-cafe-las-vegas-strip.a438498.detalles-actividades
...
